Workbook
Name _Hlk26540438: ИД!#REF!

Sheet Лист1
B1: Вид дефекта | D1: Значение показателя ρ при типе дорожных одежд
C2: Оценка в баллах | D2: Усовершен- ствованные капитальные | E2: Усовершен- ствованные облегченные | F2: Переходные
B3: 1 | C3: 2 | D3: 3 | E3: 4 | F3: 5
A4: без деф | B4: без дефектов; | C4: 5 | D4: 1 | E4: 1 | F4: 1
A5: пт2040 | B5: поперечные одиночные трещины на расстоянии 20-40 м между трещинами; | C5: 4.9 | D5: 0.95 | E5: 1 | F5: 0.9
A6: пт1020 | B6: поперечные одиночные трещины на расстоянии 10-20 м; | C6: 4.6 | D6: 0.9 | E6: 0.95 | F6: 0.8
A7: пт810 | B7: поперечные редкие трещины на расстоянии 8-10 м; | C7: 4.3 | D7: 0.85 | E7: 0.9 | F7: 0.7
A8: пт68 | B8: поперечные редкие трещины на расстоянии 6-8 м; | C8: 3.9 | D8: 0.8 | E8: 0.85 | F8: 0.55
A9: пт46 | B9: поперечные редкие трещины на расстоянии 4-6 м; | C9: 3.6 | D9: 0.78 | E9: 0.83 | F9: 0.42
A10: пт34 | B10: поперечные частые трещины на расстоянии 3-4 м; | C10: 3.2 | D10: 0.75 | E10: 0.8 | F10: -
A11: пт23 | B11: поперечные частые трещины на расстоянии 2-3 м; | C11: 2.9 | D11: 0.7 | E11: 0.75 | F11: -
A12: пт12 | B12: поперечные частые трещины на расстоянии 1-2 м; | C12: 2.6 | D12: 0.65 | E12: 0.7 | F12: -
A13: по | B13: продольная центральная трещина; | C13: 4.5 | D13: 0.9 | E13: 0.95 | F13: -
A14: пб | B14: продольные боковые трещины; | C14: 3.5 | D14: 0.9 | E14: 0.85 | F14: -
A15: зпт2040 | B15: залитые поперечные одиночные трещины на расстоянии 20-40 м между трещинами; | C15: 4.9 | D15: 0.95 | E15: 1 | F15: 0.9
A16: зпт1020 | B16: залитые поперечные одиночные трещины на расстоянии 10-20 м; | C16: 4.6 | D16: 0.9 | E16: 0.95 | F16: 0.8
A17: зпт810 | B17: залитые поперечные редкие трещины на расстоянии 8-10 м; | C17: 4.3 | D17: 0.85 | E17: 0.9 | F17: 0.7
A18: зпт68 | B18: залитые поперечные редкие трещины на расстоянии 6-8 м; | C18: 3.9 | D18: 0.8 | E18: 0.85 | F18: 0.55
A19: зпт46 | B19: залитые поперечные редкие трещины на расстоянии 4-6 м; | C19: 3.6 | D19: 0.78 | E19: 0.83 | F19: 0.42
A20: зпт34 | B20: залитые поперечные частые трещины на расстоянии 3-4 м; | C20: 3.2 | D20: 0.75 | E20: 0.8 | F20: -
A21: зпт23 | B21: залитые поперечные частые трещины на расстоянии 2-3 м; | C21: 2.9 | D21: 0.7 | E21: 0.75 | F21: -
A22: зпт12 | B22: залитые поперечные частые трещины на расстоянии 1-2 м; | C22: 2.6 | D22: 0.65 | E22: 0.7 | F22: -
A23: зпб | B23: залитые продольные боковые трещины; | C23: 3.5 | D23: 0.9 | E23: 0.85 | F23: -
A24: кос | B24: косые трещины; | C24: 3 | D24: 0.75 | E24: 0.8 | F24: 0.8
A25: одкр | B25: одиночная сетка трещин на площади до 10 м с крупными ячейками (сторона ячейки более 0,5 м); | C25: 3 | D25: 0.75 | E25: 0.8 | F25: -
A26: одмел | B26: одиночная сетка трещин на площади до 10 м с мелкими ячейками (сторона ячейки менее 0,5 м); | C26: 2.5 | D26: 0.65 | E26: 0.7
A27: гсет | B27: густая сетка трещин на площади до 10 м; | C27: 2 | D27: 0.6 | E27: 0.65
A28: мс30 | B28: сетка трещин на площади более 10м при относительной площади, занимаемой сеткой, 30-10%; | C28: 2.3 | D28: 0.6 | E28: 0.65 | F28: -
A29: мс60 | B29: сетка трещин на площади более 10м при относительной площади, 60-30%; | C29: 1.9 | D29: 0.55 | E29: 0.6 | F29: -
A30: мс90 | B30: сетка трещин на площади более 10м при относительной площади, 90-60%; | C30: 1.6 | D30: 0.5 | E30: 0.55 | F30: -
A31: кол10 | B31: колейность при средней глубине колеи до 10 мм; | C31: 5
A32: кол20 | B32: колейность при средней глубине колеи 10-20 мм; | C32: 5
A33: кол30 | B33: колейность при средней глубине колеи 20-30 мм; | C33: 5
A34: кол40 | B34: колейность при средней глубине колеи 30-40 мм; | C34: 5
A35: кол50 | B35: колейность при средней глубине колеи 40-50 мм; | C35: 5
A36: кол70 | B36: колейность при средней глубине колеи 50-70 мм; | C36: 5
A37: кол80 | B37: колейность при средней глубине колеи более 70 мм; | C37: 5
A38: прос10 | B38: просадки (пучины) при относительной площади просадок 20-10%; | C38: 1.2 | D38: 0.45 | E38: 0.5 | F38: 0.35
A39: прос20 | B39: просадки (пучины) при относительной площади просадок 50-20%; | C39: 0.9 | D39: 0.4 | E39: 0.45 | F39: 0.3
A40: прос50 | B40: просадки (пучины) при относительной площади просадок более 50%; | C40: 0.5 | D40: 0.35 | E40: 0.4 | F40: 0.25
...

Sheet ИД
D1: № | E1: Наименование | F1: Категория | G1: Покрытие | H1: Принадлежность | I1: Осевая нагрузка | J1: Используемый участок | K1: Ширина | L1: Протяженность | M1: Фото | N1: Принадлежность | P1: Наличие маршрута в книге | Q1: от | R1: до | T1: Широта начало | U1: Долгота начало | V1: Широта конец | W1: Долгота конец | Z1: =IFERROR(INDIRECT(CONCATENATE(IF(ISBLANK(#REF!),#REF!,#REF!& "."&#REF!),"!O9")), "маршрута нет") -> маршрута нет

Sheet В обсл
A1: № | B1: Наименование | C1: Категория | D1: Покрытие | E1: Осевая нагрузка | F1: Протяженность | G1: Принадлежность | I1: Широта начало | J1: Долгота начало | K1: Широта конец | L1: Долгота конец

Sheet аб1
B1: =MID(CELL("ИМЯФАЙЛА",A1),SEARCH("]",CELL("ИМЯФАЙЛА",A1))+1,255) -> аб1 | C1: =VLOOKUP(B1,ИД!D2:R238,2,FALSE) -> #N/A | O1: =TRIM(RIGHT(SUBSTITUTE(E3,",",REPT(" ",5)),5)) -> #N/A
B2: =IF(N2=1,"федеральной",IF(N2=2,"региональной",IF(N2=3,"местной",IF(N2=4,"частной",IF(N2=5,"лесной","ведомственной"))))) -> #N/A | C2: Тип ДО | E2: облегченная | G2: Бср | K2: =ROUND(SUM(AQ12:AQ131)/(SUM(C12:C131)-E4),1) -> #DIV/0! | N2: =VLOOKUP(B1,ИД!D2:R238,12,FALSE) -> #N/A | O2: =LOWER(LEFT(C1,1))&RIGHT(C1,LEN(C1)-1) -> #N/A | AM2: =CONCATENATE(Лист1!B94,K2,Лист1!B95,K4,Лист1!B96,O3) -> #DIV/0!
B3: дорога | C3: Категория | E3: =VLOOKUP(B1,ИД!D2:R238,3,FALSE) -> #N/A | G3: Протяженность | K3: =SUMIF(C12:C131,">0") -> 0 | N3: =VLOOKUP(O1,Лист1!A75:C81,2,FALSE) -> #N/A | O3: =IF(4<K2,Лист1!B88,IF(3<K2,Лист1!B89,IF(2<K2,Лист1!B90,Лист1!B91))) -> #DIV/0! | AU3: «»
B4: =VLOOKUP(B1,ИД!D2:R238,9,FALSE) -> #N/A | C4: Прот ПГС; грунт | E4: 0 | G4: Кпр | K4: =ROUND(0.5+K2/10,2) -> #DIV/0! | N4: =VLOOKUP(O1,Лист1!A75:C81,3,FALSE) -> #N/A
B5: =VLOOKUP(B1,ИД!D2:R238,4,FALSE) -> #N/A | C5: Начало, км | E5: 0 | G5: фото | K5: =VLOOKUP(B1,ИД!D2:R238,10,FALSE) -> #N/A | N5: дорога | O5: ="Маршрут № "&B1&" представляет собой участок "&B2&" автомобильной дороги «"&C1&"», который начинается от "&D6&" и следует до "&D7&"." -> #N/A
B6: =VLOOKUP(B1,ИД!D2:R238,8,FALSE) -> #N/A | C6: от | D6: =VLOOKUP(B1,ИД!D2:R238,14,FALSE) -> #N/A | N6: улица | O6: ="Маршрут № "&B1&" представляет собой участок "&C1&", который начинается от "&D6&" и следует до "&D7&"." -> #N/A | AM6: =VLOOKUP(B3,N5:O7,2,FALSE) -> #N/A
B7: =VLOOKUP(B1,ИД!D2:R238,11,FALSE) -> #N/A | C7: до | D7: =VLOOKUP(B1,ИД!D2:R238,15,FALSE) -> #N/A | N7: подъезд | O7: ="Маршрут № "&B1&" представляет собой "&LOWER(LEFT(C1,1))&RIGHT(C1,LEN(C1)-1)&" от "&D6&"." -> #N/A
B9: =HYPERLINK("#ИД!D"&MATCH(B1, ИД!D:D, 0), "На лист ИД!") -> #N/A | O9: маршрут есть
D11: ширина | E11: покрытие | M11: Для заметок (свои дефекты, дефекты на плитах итд) | AE11: =E5 -> 0
A12: 0 | B12: 0 | C12: =B12-A12 -> 0 | N12: =IFERROR(VLOOKUP($F12,Лист1!$A$4:$F$72,2,FALSE),"") | O12: =IFERROR(VLOOKUP($G12,Лист1!$A$4:$F$72,2,FALSE),"") | P12: =IFERROR(VLOOKUP($H12,Лист1!$A$4:$F$72,2,FALSE),"") | Q12: =IFERROR(VLOOKUP($I12,Лист1!$A$4:$F$72,2,FALSE),"") | R12: =IFERROR(VLOOKUP($J12,Лист1!$A$4:$F$72,2,FALSE),"") | S12: =IFERROR(VLOOKUP($K12,Лист1!$A$4:$F$72,2,FALSE),"") | T12: =IFERROR(VLOOKUP($L12,Лист1!$A$4:$F$72,2,FALSE),"") | U12: =IF(ISBLANK($M12),"",$M12) | V12: =IFERROR(VLOOKUP($F12,Лист1!$A$4:$F$72,3,FALSE),"") | W12: =IFERROR(VLOOKUP($G12,Лист1!$A$4:$F$72,3,FALSE),"") | X12: =IFERROR(VLOOKUP($H12,Лист1!$A$4:$F$72,3,FALSE),"") | Y12: =IFERROR(VLOOKUP($I12,Лист1!$A$4:$F$72,3,FALSE),"") | Z12: =IFERROR(VLOOKUP($J12,Лист1!$A$4:$F$72,3,FALSE),"") | AA12: =IFERROR(VLOOKUP($K12,Лист1!$A$4:$F$72,3,FALSE),"") | AB12: =IFERROR(VLOOKUP($L12,Лист1!$A$4:$F$72,3,FALSE),"") | AC12: =IFERROR(VLOOKUP($M12,Лист1!$A$4:$F$72,3,FALSE),"") | AD12: =ROUND(AE11,3) -> 0 | AE12: =ROUND(AD12+C12,3) -> 0 | AF12: =ROUND(ROUNDDOWN(AD12,0),0) -> 0 | AG12: =ROUND((AD12-AF12)*1000,0) -> 0 | AH12: =ROUND(ROUNDDOWN(AE12,0),0) -> 0 | AI12: =ROUND((AE12-AH12)*1000,0) -> 0 | AJ12: =IF($AG12=0,"000",$AG12) -> 000 | AK12: =IF($AI12=0,"000",$AI12) -> 000 | AM12: =CONCATENATE("км ",AF12,"+",AJ12," - км ",AH12,"+",AK12) -> км 0+000 - км 0+000 | AN12: =IF(ISBLANK($M12),N12&O12&P12&Q12&R12&S12&T12&U12,N12&O12&P12&Q12&R12&S12&T12&U12&";") | AO12: =UPPER(LEFT($AN12,1))&RIGHT(LOWER($AN12),LEN($AN12)-1) -> #VALUE! | AP12: =MIN(V12:AC12) -> 0 | AQ12: =AP12*$C12 -> 0 | AS12: =AD12 -> 0 | AT12: =AE12 -> 0 | AU12: =E12 -> 0 | AV12: =D12 -> 0 | AW12: =IF(AP12=0,"-",AP12) -> - | AY12: =$AM12 -> км 0+000 - км 0+000 | AZ12: =$AW12 -> - | BA12: =$BE12 -> 0.5 | BD12: =$AM12 -> км 0+000 - км 0+000 | BE12: =ROUND(1-((5-$AP12)/10),2) -> 0.5 | BF12: =ROUND(BE12*$N$4,0) -> #N/A
A13: =B12 -> 0 | C13: =B13-A13 -> 0 | N13: =IFERROR(VLOOKUP($F13,Лист1!$A$4:$F$72,2,FALSE),"") | O13: =IFERROR(VLOOKUP($G13,Лист1!$A$4:$F$72,2,FALSE),"") | P13: =IFERROR(VLOOKUP($H13,Лист1!$A$4:$F$72,2,FALSE),"") | Q13: =IFERROR(VLOOKUP($I13,Лист1!$A$4:$F$72,2,FALSE),"") | R13: =IFERROR(VLOOKUP($J13,Лист1!$A$4:$F$72,2,FALSE),"") | S13: =IFERROR(VLOOKUP($K13,Лист1!$A$4:$F$72,2,FALSE),"") | T13: =IFERROR(VLOOKUP($L13,Лист1!$A$4:$F$72,2,FALSE),"") | U13: =IF(ISBLANK($M13),"",$M13) | V13: =IFERROR(VLOOKUP($F13,Лист1!$A$4:$F$72,3,FALSE),"") | W13: =IFERROR(VLOOKUP($G13,Лист1!$A$4:$F$72,3,FALSE),"") | X13: =IFERROR(VLOOKUP($H13,Лист1!$A$4:$F$72,3,FALSE),"") | Y13: =IFERROR(VLOOKUP($I13,Лист1!$A$4:$F$72,3,FALSE),"") | Z13: =IFERROR(VLOOKUP($J13,Лист1!$A$4:$F$72,3,FALSE),"") | AA13: =IFERROR(VLOOKUP($K13,Лист1!$A$4:$F$72,3,FALSE),"") | AB13: =IFERROR(VLOOKUP($L13,Лист1!$A$4:$F$72,3,FALSE),"") | AC13: =IFERROR(VLOOKUP($M13,Лист1!$A$4:$F$72,3,FALSE),"") | AD13: =ROUND(AE12,3) -> 0 | AE13: =ROUND(AD13+C13,3) -> 0 | AF13: =ROUND(ROUNDDOWN(AD13,0),0) -> 0 | AG13: =ROUND((AD13-AF13)*1000,0) -> 0 | AH13: =ROUND(ROUNDDOWN(AE13,0),0) -> 0 | AI13: =ROUND((AE13-AH13)*1000,0) -> 0 | AJ13: =IF($AG13=0,"000",$AG13) -> 000 | AK13: =IF($AI13=0,"000",$AI13) -> 000 | AM13: =CONCATENATE("км ",AF13,"+",AJ13," - км ",AH13,"+",AK13) -> км 0+000 - км 0+000 | AN13: =IF(ISBLANK($M13),N13&O13&P13&Q13&R13&S13&T13&U13,N13&O13&P13&Q13&R13&S13&T13&U13&";") | AO13: =UPPER(LEFT($AN13,1))&RIGHT(LOWER($AN13),LEN($AN13)-1) -> #VALUE! | AP13: =MIN(V13:AC13) -> 0 | AQ13: =AP13*C13 -> 0 | AS13: =AD13 -> 0 | AT13: =AE13 -> 0 | AU13: =E13 -> 0 | AV13: =D13 -> 0 | AW13: =IF(AP13=0,"-",AP13) -> - | AY13: =$AM13 -> км 0+000 - км 0+000 | AZ13: =$AW13 -> - | BA13: =$BE13 -> 0.5 | BD13: =$AM13 -> км 0+000 - км 0+000 | BE13: =ROUND(1-((5-$AP13)/10),2) -> 0.5 | BF13: =ROUND(BE13*$N$4,0) -> #N/A
A14: =B13 -> 0 | C14: =B14-A14 -> 0 | N14: =IFERROR(VLOOKUP($F14,Лист1!$A$4:$F$72,2,FALSE),"") | O14: =IFERROR(VLOOKUP($G14,Лист1!$A$4:$F$72,2,FALSE),"") | P14: =IFERROR(VLOOKUP($H14,Лист1!$A$4:$F$72,2,FALSE),"") | Q14: =IFERROR(VLOOKUP($I14,Лист1!$A$4:$F$72,2,FALSE),"") | R14: =IFERROR(VLOOKUP($J14,Лист1!$A$4:$F$72,2,FALSE),"") | S14: =IFERROR(VLOOKUP($K14,Лист1!$A$4:$F$72,2,FALSE),"") | T14: =IFERROR(VLOOKUP($L14,Лист1!$A$4:$F$72,2,FALSE),"") | U14: =IF(ISBLANK($M14),"",$M14) | V14: =IFERROR(VLOOKUP($F14,Лист1!$A$4:$F$72,3,FALSE),"") | W14: =IFERROR(VLOOKUP($G14,Лист1!$A$4:$F$72,3,FALSE),"") | X14: =IFERROR(VLOOKUP($H14,Лист1!$A$4:$F$72,3,FALSE),"") | Y14: =IFERROR(VLOOKUP($I14,Лист1!$A$4:$F$72,3,FALSE),"") | Z14: =IFERROR(VLOOKUP($J14,Лист1!$A$4:$F$72,3,FALSE),"") | AA14: =IFERROR(VLOOKUP($K14,Лист1!$A$4:$F$72,3,FALSE),"") | AB14: =IFERROR(VLOOKUP($L14,Лист1!$A$4:$F$72,3,FALSE),"") | AC14: =IFERROR(VLOOKUP($M14,Лист1!$A$4:$F$72,3,FALSE),"") | AD14: =ROUND(AE13,3) -> 0 | AE14: =ROUND(AD14+C14,3) -> 0 | AF14: =ROUND(ROUNDDOWN(AD14,0),0) -> 0 | AG14: =ROUND((AD14-AF14)*1000,0) -> 0 | AH14: =ROUND(ROUNDDOWN(AE14,0),0) -> 0 | AI14: =ROUND((AE14-AH14)*1000,0) -> 0 | AJ14: =IF($AG14=0,"000",$AG14) -> 000 | AK14: =IF($AI14=0,"000",$AI14) -> 000 | AM14: =CONCATENATE("км ",AF14,"+",AJ14," - км ",AH14,"+",AK14) -> км 0+000 - км 0+000 | AN14: =IF(ISBLANK($M14),N14&O14&P14&Q14&R14&S14&T14&U14,N14&O14&P14&Q14&R14&S14&T14&U14&";") | AO14: =UPPER(LEFT($AN14,1))&RIGHT(LOWER($AN14),LEN($AN14)-1) -> #VALUE! | AP14: =MIN(V14:AC14) -> 0 | AQ14: =AP14*C14 -> 0 | AS14: =AD14 -> 0 | AT14: =AE14 -> 0 | AU14: =E14 -> 0 | AV14: =D14 -> 0 | AW14: =IF(AP14=0,"-",AP14) -> - | AY14: =$AM14 -> км 0+000 - км 0+000 | AZ14: =$AW14 -> - | BA14: =$BE14 -> 0.5 | BD14: =$AM14 -> км 0+000 - км 0+000 | BE14: =ROUND(1-((5-$AP14)/10),2) -> 0.5 | BF14: =ROUND(BE14*$N$4,0) -> #N/A
A15: =B14 -> 0 | C15: =B15-A15 -> 0 | N15: =IFERROR(VLOOKUP($F15,Лист1!$A$4:$F$72,2,FALSE),"") | O15: =IFERROR(VLOOKUP($G15,Лист1!$A$4:$F$72,2,FALSE),"") | P15: =IFERROR(VLOOKUP($H15,Лист1!$A$4:$F$72,2,FALSE),"") | Q15: =IFERROR(VLOOKUP($I15,Лист1!$A$4:$F$72,2,FALSE),"") | R15: =IFERROR(VLOOKUP($J15,Лист1!$A$4:$F$72,2,FALSE),"") | S15: =IFERROR(VLOOKUP($K15,Лист1!$A$4:$F$72,2,FALSE),"") | T15: =IFERROR(VLOOKUP($L15,Лист1!$A$4:$F$72,2,FALSE),"") | U15: =IF(ISBLANK($M15),"",$M15) | V15: =IFERROR(VLOOKUP($F15,Лист1!$A$4:$F$72,3,FALSE),"") | W15: =IFERROR(VLOOKUP($G15,Лист1!$A$4:$F$72,3,FALSE),"") | X15: =IFERROR(VLOOKUP($H15,Лист1!$A$4:$F$72,3,FALSE),"") | Y15: =IFERROR(VLOOKUP($I15,Лист1!$A$4:$F$72,3,FALSE),"") | Z15: =IFERROR(VLOOKUP($J15,Лист1!$A$4:$F$72,3,FALSE),"") | AA15: =IFERROR(VLOOKUP($K15,Лист1!$A$4:$F$72,3,FALSE),"") | AB15: =IFERROR(VLOOKUP($L15,Лист1!$A$4:$F$72,3,FALSE),"") | AC15: =IFERROR(VLOOKUP($M15,Лист1!$A$4:$F$72,3,FALSE),"") | AD15: =ROUND(AE14,3) -> 0 | AE15: =ROUND(AD15+C15,3) -> 0 | AF15: =ROUND(ROUNDDOWN(AD15,0),0) -> 0 | AG15: =ROUND((AD15-AF15)*1000,0) -> 0 | AH15: =ROUND(ROUNDDOWN(AE15,0),0) -> 0 | AI15: =ROUND((AE15-AH15)*1000,0) -> 0 | AJ15: =IF($AG15=0,"000",$AG15) -> 000 | AK15: =IF($AI15=0,"000",$AI15) -> 000 | AM15: =CONCATENATE("км ",AF15,"+",AJ15," - км ",AH15,"+",AK15) -> км 0+000 - км 0+000 | AN15: =IF(ISBLANK($M15),N15&O15&P15&Q15&R15&S15&T15&U15,N15&O15&P15&Q15&R15&S15&T15&U15&";") | AO15: =UPPER(LEFT($AN15,1))&RIGHT(LOWER($AN15),LEN($AN15)-1) -> #VALUE! | AP15: =MIN(V15:AC15) -> 0 | AQ15: =AP15*C15 -> 0 | AS15: =AD15 -> 0 | AT15: =AE15 -> 0 | AU15: =E15 -> 0 | AV15: =D15 -> 0 | AW15: =IF(AP15=0,"-",AP15) -> - | AY15: =$AM15 -> км 0+000 - км 0+000 | AZ15: =$AW15 -> - | BA15: =$BE15 -> 0.5 | BD15: =$AM15 -> км 0+000 - км 0+000 | BE15: =ROUND(1-((5-$AP15)/10),2) -> 0.5 | BF15: =ROUND(BE15*$N$4,0) -> #N/A
A16: =B15 -> 0 | C16: =B16-A16 -> 0 | N16: =IFERROR(VLOOKUP($F16,Лист1!$A$4:$F$72,2,FALSE),"") | O16: =IFERROR(VLOOKUP($G16,Лист1!$A$4:$F$72,2,FALSE),"") | P16: =IFERROR(VLOOKUP($H16,Лист1!$A$4:$F$72,2,FALSE),"") | Q16: =IFERROR(VLOOKUP($I16,Лист1!$A$4:$F$72,2,FALSE),"") | R16: =IFERROR(VLOOKUP($J16,Лист1!$A$4:$F$72,2,FALSE),"") | S16: =IFERROR(VLOOKUP($K16,Лист1!$A$4:$F$72,2,FALSE),"") | T16: =IFERROR(VLOOKUP($L16,Лист1!$A$4:$F$72,2,FALSE),"") | U16: =IF(ISBLANK($M16),"",$M16) | V16: =IFERROR(VLOOKUP($F16,Лист1!$A$4:$F$72,3,FALSE),"") | W16: =IFERROR(VLOOKUP($G16,Лист1!$A$4:$F$72,3,FALSE),"") | X16: =IFERROR(VLOOKUP($H16,Лист1!$A$4:$F$72,3,FALSE),"") | Y16: =IFERROR(VLOOKUP($I16,Лист1!$A$4:$F$72,3,FALSE),"") | Z16: =IFERROR(VLOOKUP($J16,Лист1!$A$4:$F$72,3,FALSE),"") | AA16: =IFERROR(VLOOKUP($K16,Лист1!$A$4:$F$72,3,FALSE),"") | AB16: =IFERROR(VLOOKUP($L16,Лист1!$A$4:$F$72,3,FALSE),"") | AC16: =IFERROR(VLOOKUP($M16,Лист1!$A$4:$F$72,3,FALSE),"") | AD16: =ROUND(AE15,3) -> 0 | AE16: =ROUND(AD16+C16,3) -> 0 | AF16: =ROUND(ROUNDDOWN(AD16,0),0) -> 0 | AG16: =ROUND((AD16-AF16)*1000,0) -> 0 | AH16: =ROUND(ROUNDDOWN(AE16,0),0) -> 0 | AI16: =ROUND((AE16-AH16)*1000,0) -> 0 | AJ16: =IF($AG16=0,"000",$AG16) -> 000 | AK16: =IF($AI16=0,"000",$AI16) -> 000 | AM16: =CONCATENATE("км ",AF16,"+",AJ16," - км ",AH16,"+",AK16) -> км 0+000 - км 0+000 | AN16: =IF(ISBLANK($M16),N16&O16&P16&Q16&R16&S16&T16&U16,N16&O16&P16&Q16&R16&S16&T16&U16&";") | AO16: =UPPER(LEFT($AN16,1))&RIGHT(LOWER($AN16),LEN($AN16)-1) -> #VALUE! | AP16: =MIN(V16:AC16) -> 0 | AQ16: =AP16*C16 -> 0 | AS16: =AD16 -> 0 | AT16: =AE16 -> 0 | AU16: =E16 -> 0 | AV16: =D16 -> 0 | AW16: =IF(AP16=0,"-",AP16) -> - | AY16: =$AM16 -> км 0+000 - км 0+000 | AZ16: =$AW16 -> - | BA16: =$BE16 -> 0.5 | BD16: =$AM16 -> км 0+000 - км 0+000 | BE16: =ROUND(1-((5-$AP16)/10),2) -> 0.5 | BF16: =ROUND(BE16*$N$4,0) -> #N/A
A17: =B16 -> 0 | C17: =B17-A17 -> 0 | N17: =IFERROR(VLOOKUP($F17,Лист1!$A$4:$F$72,2,FALSE),"") | O17: =IFERROR(VLOOKUP($G17,Лист1!$A$4:$F$72,2,FALSE),"") | P17: =IFERROR(VLOOKUP($H17,Лист1!$A$4:$F$72,2,FALSE),"") | Q17: =IFERROR(VLOOKUP($I17,Лист1!$A$4:$F$72,2,FALSE),"") | R17: =IFERROR(VLOOKUP($J17,Лист1!$A$4:$F$72,2,FALSE),"") | S17: =IFERROR(VLOOKUP($K17,Лист1!$A$4:$F$72,2,FALSE),"") | T17: =IFERROR(VLOOKUP($L17,Лист1!$A$4:$F$72,2,FALSE),"") | U17: =IF(ISBLANK($M17),"",$M17) | V17: =IFERROR(VLOOKUP($F17,Лист1!$A$4:$F$72,3,FALSE),"") | W17: =IFERROR(VLOOKUP($G17,Лист1!$A$4:$F$72,3,FALSE),"") | X17: =IFERROR(VLOOKUP($H17,Лист1!$A$4:$F$72,3,FALSE),"") | Y17: =IFERROR(VLOOKUP($I17,Лист1!$A$4:$F$72,3,FALSE),"") | Z17: =IFERROR(VLOOKUP($J17,Лист1!$A$4:$F$72,3,FALSE),"") | AA17: =IFERROR(VLOOKUP($K17,Лист1!$A$4:$F$72,3,FALSE),"") | AB17: =IFERROR(VLOOKUP($L17,Лист1!$A$4:$F$72,3,FALSE),"") | AC17: =IFERROR(VLOOKUP($M17,Лист1!$A$4:$F$72,3,FALSE),"") | AD17: =ROUND(AE16,3) -> 0 | AE17: =ROUND(AD17+C17,3) -> 0 | AF17: =ROUND(ROUNDDOWN(AD17,0),0) -> 0 | AG17: =ROUND((AD17-AF17)*1000,0) -> 0 | AH17: =ROUND(ROUNDDOWN(AE17,0),0) -> 0 | AI17: =ROUND((AE17-AH17)*1000,0) -> 0 | AJ17: =IF($AG17=0,"000",$AG17) -> 000 | AK17: =IF($AI17=0,"000",$AI17) -> 000 | AM17: =CONCATENATE("км ",AF17,"+",AJ17," - км ",AH17,"+",AK17) -> км 0+000 - км 0+000 | AN17: =IF(ISBLANK($M17),N17&O17&P17&Q17&R17&S17&T17&U17,N17&O17&P17&Q17&R17&S17&T17&U17&";") | AO17: =UPPER(LEFT($AN17,1))&RIGHT(LOWER($AN17),LEN($AN17)-1) -> #VALUE! | AP17: =MIN(V17:AC17) -> 0 | AQ17: =AP17*C17 -> 0 | AS17: =AD17 -> 0 | AT17: =AE17 -> 0 | AU17: =E17 -> 0 | AV17: =D17 -> 0 | AW17: =IF(AP17=0,"-",AP17) -> - | AY17: =$AM17 -> км 0+000 - км 0+000 | AZ17: =$AW17 -> - | BA17: =$BE17 -> 0.5 | BD17: =$AM17 -> км 0+000 - км 0+000 | BE17: =ROUND(1-((5-$AP17)/10),2) -> 0.5 | BF17: =ROUND(BE17*$N$4,0) -> #N/A
A18: =B17 -> 0 | C18: =B18-A18 -> 0 | N18: =IFERROR(VLOOKUP($F18,Лист1!$A$4:$F$72,2,FALSE),"") | O18: =IFERROR(VLOOKUP($G18,Лист1!$A$4:$F$72,2,FALSE),"") | P18: =IFERROR(VLOOKUP($H18,Лист1!$A$4:$F$72,2,FALSE),"") | Q18: =IFERROR(VLOOKUP($I18,Лист1!$A$4:$F$72,2,FALSE),"") | R18: =IFERROR(VLOOKUP($J18,Лист1!$A$4:$F$72,2,FALSE),"") | S18: =IFERROR(VLOOKUP($K18,Лист1!$A$4:$F$72,2,FALSE),"") | T18: =IFERROR(VLOOKUP($L18,Лист1!$A$4:$F$72,2,FALSE),"") | U18: =IF(ISBLANK($M18),"",$M18) | V18: =IFERROR(VLOOKUP($F18,Лист1!$A$4:$F$72,3,FALSE),"") | W18: =IFERROR(VLOOKUP($G18,Лист1!$A$4:$F$72,3,FALSE),"") | X18: =IFERROR(VLOOKUP($H18,Лист1!$A$4:$F$72,3,FALSE),"") | Y18: =IFERROR(VLOOKUP($I18,Лист1!$A$4:$F$72,3,FALSE),"") | Z18: =IFERROR(VLOOKUP($J18,Лист1!$A$4:$F$72,3,FALSE),"") | AA18: =IFERROR(VLOOKUP($K18,Лист1!$A$4:$F$72,3,FALSE),"") | AB18: =IFERROR(VLOOKUP($L18,Лист1!$A$4:$F$72,3,FALSE),"") | AC18: =IFERROR(VLOOKUP($M18,Лист1!$A$4:$F$72,3,FALSE),"") | AD18: =ROUND(AE17,3) -> 0 | AE18: =ROUND(AD18+C18,3) -> 0 | AF18: =ROUND(ROUNDDOWN(AD18,0),0) -> 0 | AG18: =ROUND((AD18-AF18)*1000,0) -> 0 | AH18: =ROUND(ROUNDDOWN(AE18,0),0) -> 0 | AI18: =ROUND((AE18-AH18)*1000,0) -> 0 | AJ18: =IF($AG18=0,"000",$AG18) -> 000 | AK18: =IF($AI18=0,"000",$AI18) -> 000 | AM18: =CONCATENATE("км ",AF18,"+",AJ18," - км ",AH18,"+",AK18) -> км 0+000 - км 0+000 | AN18: =IF(ISBLANK($M18),N18&O18&P18&Q18&R18&S18&T18&U18,N18&O18&P18&Q18&R18&S18&T18&U18&";") | AO18: =UPPER(LEFT($AN18,1))&RIGHT(LOWER($AN18),LEN($AN18)-1) -> #VALUE! | AP18: =MIN(V18:AC18) -> 0 | AQ18: =AP18*C18 -> 0 | AS18: =AD18 -> 0 | AT18: =AE18 -> 0 | AU18: =E18 -> 0 | AV18: =D18 -> 0 | AW18: =IF(AP18=0,"-",AP18) -> - | AY18: =$AM18 -> км 0+000 - км 0+000 | AZ18: =$AW18 -> - | BA18: =$BE18 -> 0.5 | BD18: =$AM18 -> км 0+000 - км 0+000 | BE18: =ROUND(1-((5-$AP18)/10),2) -> 0.5 | BF18: =ROUND(BE18*$N$4,0) -> #N/A
A19: =B18 -> 0 | C19: =B19-A19 -> 0 | N19: =IFERROR(VLOOKUP($F19,Лист1!$A$4:$F$72,2,FALSE),"") | O19: =IFERROR(VLOOKUP($G19,Лист1!$A$4:$F$72,2,FALSE),"") | P19: =IFERROR(VLOOKUP($H19,Лист1!$A$4:$F$72,2,FALSE),"") | Q19: =IFERROR(VLOOKUP($I19,Лист1!$A$4:$F$72,2,FALSE),"") | R19: =IFERROR(VLOOKUP($J19,Лист1!$A$4:$F$72,2,FALSE),"") | S19: =IFERROR(VLOOKUP($K19,Лист1!$A$4:$F$72,2,FALSE),"") | T19: =IFERROR(VLOOKUP($L19,Лист1!$A$4:$F$72,2,FALSE),"") | U19: =IF(ISBLANK($M19),"",$M19) | V19: =IFERROR(VLOOKUP($F19,Лист1!$A$4:$F$72,3,FALSE),"") | W19: =IFERROR(VLOOKUP($G19,Лист1!$A$4:$F$72,3,FALSE),"") | X19: =IFERROR(VLOOKUP($H19,Лист1!$A$4:$F$72,3,FALSE),"") | Y19: =IFERROR(VLOOKUP($I19,Лист1!$A$4:$F$72,3,FALSE),"") | Z19: =IFERROR(VLOOKUP($J19,Лист1!$A$4:$F$72,3,FALSE),"") | AA19: =IFERROR(VLOOKUP($K19,Лист1!$A$4:$F$72,3,FALSE),"") | AB19: =IFERROR(VLOOKUP($L19,Лист1!$A$4:$F$72,3,FALSE),"") | AC19: =IFERROR(VLOOKUP($M19,Лист1!$A$4:$F$72,3,FALSE),"") | AD19: =ROUND(AE18,3) -> 0 | AE19: =ROUND(AD19+C19,3) -> 0 | AF19: =ROUND(ROUNDDOWN(AD19,0),0) -> 0 | AG19: =ROUND((AD19-AF19)*1000,0) -> 0 | AH19: =ROUND(ROUNDDOWN(AE19,0),0) -> 0 | AI19: =ROUND((AE19-AH19)*1000,0) -> 0 | AJ19: =IF($AG19=0,"000",$AG19) -> 000 | AK19: =IF($AI19=0,"000",$AI19) -> 000 | AM19: =CONCATENATE("км ",AF19,"+",AJ19," - км ",AH19,"+",AK19) -> км 0+000 - км 0+000 | AN19: =IF(ISBLANK($M19),N19&O19&P19&Q19&R19&S19&T19&U19,N19&O19&P19&Q19&R19&S19&T19&U19&";") | AO19: =UPPER(LEFT($AN19,1))&RIGHT(LOWER($AN19),LEN($AN19)-1) -> #VALUE! | AP19: =MIN(V19:AC19) -> 0 | AQ19: =AP19*C19 -> 0 | AS19: =AD19 -> 0 | AT19: =AE19 -> 0 | AU19: =E19 -> 0 | AV19: =D19 -> 0 | AW19: =IF(AP19=0,"-",AP19) -> - | AY19: =$AM19 -> км 0+000 - км 0+000 | AZ19: =$AW19 -> - | BA19: =$BE19 -> 0.5 | BD19: =$AM19 -> км 0+000 - км 0+000 | BE19: =ROUND(1-((5-$AP19)/10),2) -> 0.5 | BF19: =ROUND(BE19*$N$4,0) -> #N/A
A20: =B19 -> 0 | C20: =B20-A20 -> 0 | N20: =IFERROR(VLOOKUP($F20,Лист1!$A$4:$F$72,2,FALSE),"") | O20: =IFERROR(VLOOKUP($G20,Лист1!$A$4:$F$72,2,FALSE),"") | P20: =IFERROR(VLOOKUP($H20,Лист1!$A$4:$F$72,2,FALSE),"") | Q20: =IFERROR(VLOOKUP($I20,Лист1!$A$4:$F$72,2,FALSE),"") | R20: =IFERROR(VLOOKUP($J20,Лист1!$A$4:$F$72,2,FALSE),"") | S20: =IFERROR(VLOOKUP($K20,Лист1!$A$4:$F$72,2,FALSE),"") | T20: =IFERROR(VLOOKUP($L20,Лист1!$A$4:$F$72,2,FALSE),"") | U20: =IF(ISBLANK($M20),"",$M20) | V20: =IFERROR(VLOOKUP($F20,Лист1!$A$4:$F$72,3,FALSE),"") | W20: =IFERROR(VLOOKUP($G20,Лист1!$A$4:$F$72,3,FALSE),"") | X20: =IFERROR(VLOOKUP($H20,Лист1!$A$4:$F$72,3,FALSE),"") | Y20: =IFERROR(VLOOKUP($I20,Лист1!$A$4:$F$72,3,FALSE),"") | Z20: =IFERROR(VLOOKUP($J20,Лист1!$A$4:$F$72,3,FALSE),"") | AA20: =IFERROR(VLOOKUP($K20,Лист1!$A$4:$F$72,3,FALSE),"") | AB20: =IFERROR(VLOOKUP($L20,Лист1!$A$4:$F$72,3,FALSE),"") | AC20: =IFERROR(VLOOKUP($M20,Лист1!$A$4:$F$72,3,FALSE),"") | AD20: =ROUND(AE19,3) -> 0 | AE20: =ROUND(AD20+C20,3) -> 0 | AF20: =ROUND(ROUNDDOWN(AD20,0),0) -> 0 | AG20: =ROUND((AD20-AF20)*1000,0) -> 0 | AH20: =ROUND(ROUNDDOWN(AE20,0),0) -> 0 | AI20: =ROUND((AE20-AH20)*1000,0) -> 0 | AJ20: =IF($AG20=0,"000",$AG20) -> 000 | AK20: =IF($AI20=0,"000",$AI20) -> 000 | AM20: =CONCATENATE("км ",AF20,"+",AJ20," - км ",AH20,"+",AK20) -> км 0+000 - км 0+000 | AN20: =IF(ISBLANK($M20),N20&O20&P20&Q20&R20&S20&T20&U20,N20&O20&P20&Q20&R20&S20&T20&U20&";") | AO20: =UPPER(LEFT($AN20,1))&RIGHT(LOWER($AN20),LEN($AN20)-1) -> #VALUE! | AP20: =MIN(V20:AC20) -> 0 | AQ20: =AP20*C20 -> 0 | AS20: =AD20 -> 0 | AT20: =AE20 -> 0 | AU20: =E20 -> 0 | AV20: =D20 -> 0 | AW20: =IF(AP20=0,"-",AP20) -> - | AY20: =$AM20 -> км 0+000 - км 0+000 | AZ20: =$AW20 -> - | BA20: =$BE20 -> 0.5 | BD20: =$AM20 -> км 0+000 - км 0+000 | BE20: =ROUND(1-((5-$AP20)/10),2) -> 0.5 | BF20: =ROUND(BE20*$N$4,0) -> #N/A
A21: =B20 -> 0 | C21: =B21-A21 -> 0 | N21: =IFERROR(VLOOKUP($F21,Лист1!$A$4:$F$72,2,FALSE),"") | O21: =IFERROR(VLOOKUP($G21,Лист1!$A$4:$F$72,2,FALSE),"") | P21: =IFERROR(VLOOKUP($H21,Лист1!$A$4:$F$72,2,FALSE),"") | Q21: =IFERROR(VLOOKUP($I21,Лист1!$A$4:$F$72,2,FALSE),"") | R21: =IFERROR(VLOOKUP($J21,Лист1!$A$4:$F$72,2,FALSE),"") | S21: =IFERROR(VLOOKUP($K21,Лист1!$A$4:$F$72,2,FALSE),"") | T21: =IFERROR(VLOOKUP($L21,Лист1!$A$4:$F$72,2,FALSE),"") | U21: =IF(ISBLANK($M21),"",$M21) | V21: =IFERROR(VLOOKUP($F21,Лист1!$A$4:$F$72,3,FALSE),"") | W21: =IFERROR(VLOOKUP($G21,Лист1!$A$4:$F$72,3,FALSE),"") | X21: =IFERROR(VLOOKUP($H21,Лист1!$A$4:$F$72,3,FALSE),"") | Y21: =IFERROR(VLOOKUP($I21,Лист1!$A$4:$F$72,3,FALSE),"") | Z21: =IFERROR(VLOOKUP($J21,Лист1!$A$4:$F$72,3,FALSE),"") | AA21: =IFERROR(VLOOKUP($K21,Лист1!$A$4:$F$72,3,FALSE),"") | AB21: =IFERROR(VLOOKUP($L21,Лист1!$A$4:$F$72,3,FALSE),"") | AC21: =IFERROR(VLOOKUP($M21,Лист1!$A$4:$F$72,3,FALSE),"") | AD21: =ROUND(AE20,3) -> 0 | AE21: =ROUND(AD21+C21,3) -> 0 | AF21: =ROUND(ROUNDDOWN(AD21,0),0) -> 0 | AG21: =ROUND((AD21-AF21)*1000,0) -> 0 | AH21: =ROUND(ROUNDDOWN(AE21,0),0) -> 0 | AI21: =ROUND((AE21-AH21)*1000,0) -> 0 | AJ21: =IF($AG21=0,"000",$AG21) -> 000 | AK21: =IF($AI21=0,"000",$AI21) -> 000 | AM21: =CONCATENATE("км ",AF21,"+",AJ21," - км ",AH21,"+",AK21) -> км 0+000 - км 0+000 | AN21: =IF(ISBLANK($M21),N21&O21&P21&Q21&R21&S21&T21&U21,N21&O21&P21&Q21&R21&S21&T21&U21&";") | AO21: =UPPER(LEFT($AN21,1))&RIGHT(LOWER($AN21),LEN($AN21)-1) -> #VALUE! | AP21: =MIN(V21:AC21) -> 0 | AQ21: =AP21*C21 -> 0 | AS21: =AD21 -> 0 | AT21: =AE21 -> 0 | AU21: =E21 -> 0 | AV21: =D21 -> 0 | AW21: =IF(AP21=0,"-",AP21) -> - | AY21: =$AM21 -> км 0+000 - км 0+000 | AZ21: =$AW21 -> - | BA21: =$BE21 -> 0.5 | BD21: =$AM21 -> км 0+000 - км 0+000 | BE21: =ROUND(1-((5-$AP21)/10),2) -> 0.5 | BF21: =ROUND(BE21*$N$4,0) -> #N/A
A22: =B21 -> 0 | C22: =B22-A22 -> 0 | N22: =IFERROR(VLOOKUP($F22,Лист1!$A$4:$F$72,2,FALSE),"") | O22: =IFERROR(VLOOKUP($G22,Лист1!$A$4:$F$72,2,FALSE),"") | P22: =IFERROR(VLOOKUP($H22,Лист1!$A$4:$F$72,2,FALSE),"") | Q22: =IFERROR(VLOOKUP($I22,Лист1!$A$4:$F$72,2,FALSE),"") | R22: =IFERROR(VLOOKUP($J22,Лист1!$A$4:$F$72,2,FALSE),"") | S22: =IFERROR(VLOOKUP($K22,Лист1!$A$4:$F$72,2,FALSE),"") | T22: =IFERROR(VLOOKUP($L22,Лист1!$A$4:$F$72,2,FALSE),"") | U22: =IF(ISBLANK($M22),"",$M22) | V22: =IFERROR(VLOOKUP($F22,Лист1!$A$4:$F$72,3,FALSE),"") | W22: =IFERROR(VLOOKUP($G22,Лист1!$A$4:$F$72,3,FALSE),"") | X22: =IFERROR(VLOOKUP($H22,Лист1!$A$4:$F$72,3,FALSE),"") | Y22: =IFERROR(VLOOKUP($I22,Лист1!$A$4:$F$72,3,FALSE),"") | Z22: =IFERROR(VLOOKUP($J22,Лист1!$A$4:$F$72,3,FALSE),"") | AA22: =IFERROR(VLOOKUP($K22,Лист1!$A$4:$F$72,3,FALSE),"") | AB22: =IFERROR(VLOOKUP($L22,Лист1!$A$4:$F$72,3,FALSE),"") | AC22: =IFERROR(VLOOKUP($M22,Лист1!$A$4:$F$72,3,FALSE),"") | AD22: =ROUND(AE21,3) -> 0 | AE22: =ROUND(AD22+C22,3) -> 0 | AF22: =ROUND(ROUNDDOWN(AD22,0),0) -> 0 | AG22: =ROUND((AD22-AF22)*1000,0) -> 0 | AH22: =ROUND(ROUNDDOWN(AE22,0),0) -> 0 | AI22: =ROUND((AE22-AH22)*1000,0) -> 0 | AJ22: =IF($AG22=0,"000",$AG22) -> 000 | AK22: =IF($AI22=0,"000",$AI22) -> 000 | AM22: =CONCATENATE("км ",AF22,"+",AJ22," - км ",AH22,"+",AK22) -> км 0+000 - км 0+000 | AN22: =IF(ISBLANK($M22),N22&O22&P22&Q22&R22&S22&T22&U22,N22&O22&P22&Q22&R22&S22&T22&U22&";") | AO22: =UPPER(LEFT($AN22,1))&RIGHT(LOWER($AN22),LEN($AN22)-1) -> #VALUE! | AP22: =MIN(V22:AC22) -> 0 | AQ22: =AP22*C22 -> 0 | AS22: =AD22 -> 0 | AT22: =AE22 -> 0 | AU22: =E22 -> 0 | AV22: =D22 -> 0 | AW22: =IF(AP22=0,"-",AP22) -> - | AY22: =$AM22 -> км 0+000 - км 0+000 | AZ22: =$AW22 -> - | BA22: =$BE22 -> 0.5 | BD22: =$AM22 -> км 0+000 - км 0+000 | BE22: =ROUND(1-((5-$AP22)/10),2) -> 0.5 | BF22: =ROUND(BE22*$N$4,0) -> #N/A
A23: =B22 -> 0 | C23: =B23-A23 -> 0 | N23: =IFERROR(VLOOKUP($F23,Лист1!$A$4:$F$72,2,FALSE),"") | O23: =IFERROR(VLOOKUP($G23,Лист1!$A$4:$F$72,2,FALSE),"") | P23: =IFERROR(VLOOKUP($H23,Лист1!$A$4:$F$72,2,FALSE),"") | Q23: =IFERROR(VLOOKUP($I23,Лист1!$A$4:$F$72,2,FALSE),"") | R23: =IFERROR(VLOOKUP($J23,Лист1!$A$4:$F$72,2,FALSE),"") | S23: =IFERROR(VLOOKUP($K23,Лист1!$A$4:$F$72,2,FALSE),"") | T23: =IFERROR(VLOOKUP($L23,Лист1!$A$4:$F$72,2,FALSE),"") | U23: =IF(ISBLANK($M23),"",$M23) | V23: =IFERROR(VLOOKUP($F23,Лист1!$A$4:$F$72,3,FALSE),"") | W23: =IFERROR(VLOOKUP($G23,Лист1!$A$4:$F$72,3,FALSE),"") | X23: =IFERROR(VLOOKUP($H23,Лист1!$A$4:$F$72,3,FALSE),"") | Y23: =IFERROR(VLOOKUP($I23,Лист1!$A$4:$F$72,3,FALSE),"") | Z23: =IFERROR(VLOOKUP($J23,Лист1!$A$4:$F$72,3,FALSE),"") | AA23: =IFERROR(VLOOKUP($K23,Лист1!$A$4:$F$72,3,FALSE),"") | AB23: =IFERROR(VLOOKUP($L23,Лист1!$A$4:$F$72,3,FALSE),"") | AC23: =IFERROR(VLOOKUP($M23,Лист1!$A$4:$F$72,3,FALSE),"") | AD23: =ROUND(AE22,3) -> 0 | AE23: =ROUND(AD23+C23,3) -> 0 | AF23: =ROUND(ROUNDDOWN(AD23,0),0) -> 0 | AG23: =ROUND((AD23-AF23)*1000,0) -> 0 | AH23: =ROUND(ROUNDDOWN(AE23,0),0) -> 0 | AI23: =ROUND((AE23-AH23)*1000,0) -> 0 | AJ23: =IF($AG23=0,"000",$AG23) -> 000 | AK23: =IF($AI23=0,"000",$AI23) -> 000 | AM23: =CONCATENATE("км ",AF23,"+",AJ23," - км ",AH23,"+",AK23) -> км 0+000 - км 0+000 | AN23: =IF(ISBLANK($M23),N23&O23&P23&Q23&R23&S23&T23&U23,N23&O23&P23&Q23&R23&S23&T23&U23&";") | AO23: =UPPER(LEFT($AN23,1))&RIGHT(LOWER($AN23),LEN($AN23)-1) -> #VALUE! | AP23: =MIN(V23:AC23) -> 0 | AQ23: =AP23*C23 -> 0 | AS23: =AD23 -> 0 | AT23: =AE23 -> 0 | AU23: =E23 -> 0 | AV23: =D23 -> 0 | AW23: =IF(AP23=0,"-",AP23) -> - | AY23: =$AM23 -> км 0+000 - км 0+000 | AZ23: =$AW23 -> - | BA23: =$BE23 -> 0.5 | BD23: =$AM23 -> км 0+000 - км 0+000 | BE23: =ROUND(1-((5-$AP23)/10),2) -> 0.5 | BF23: =ROUND(BE23*$N$4,0) -> #N/A
A24: =B23 -> 0 | C24: =B24-A24 -> 0 | N24: =IFERROR(VLOOKUP($F24,Лист1!$A$4:$F$72,2,FALSE),"") | O24: =IFERROR(VLOOKUP($G24,Лист1!$A$4:$F$72,2,FALSE),"") | P24: =IFERROR(VLOOKUP($H24,Лист1!$A$4:$F$72,2,FALSE),"") | Q24: =IFERROR(VLOOKUP($I24,Лист1!$A$4:$F$72,2,FALSE),"") | R24: =IFERROR(VLOOKUP($J24,Лист1!$A$4:$F$72,2,FALSE),"") | S24: =IFERROR(VLOOKUP($K24,Лист1!$A$4:$F$72,2,FALSE),"") | T24: =IFERROR(VLOOKUP($L24,Лист1!$A$4:$F$72,2,FALSE),"") | U24: =IF(ISBLANK($M24),"",$M24) | V24: =IFERROR(VLOOKUP($F24,Лист1!$A$4:$F$72,3,FALSE),"") | W24: =IFERROR(VLOOKUP($G24,Лист1!$A$4:$F$72,3,FALSE),"") | X24: =IFERROR(VLOOKUP($H24,Лист1!$A$4:$F$72,3,FALSE),"") | Y24: =IFERROR(VLOOKUP($I24,Лист1!$A$4:$F$72,3,FALSE),"") | Z24: =IFERROR(VLOOKUP($J24,Лист1!$A$4:$F$72,3,FALSE),"") | AA24: =IFERROR(VLOOKUP($K24,Лист1!$A$4:$F$72,3,FALSE),"") | AB24: =IFERROR(VLOOKUP($L24,Лист1!$A$4:$F$72,3,FALSE),"") | AC24: =IFERROR(VLOOKUP($M24,Лист1!$A$4:$F$72,3,FALSE),"") | AD24: =ROUND(AE23,3) -> 0 | AE24: =ROUND(AD24+C24,3) -> 0 | AF24: =ROUND(ROUNDDOWN(AD24,0),0) -> 0 | AG24: =ROUND((AD24-AF24)*1000,0) -> 0 | AH24: =ROUND(ROUNDDOWN(AE24,0),0) -> 0 | AI24: =ROUND((AE24-AH24)*1000,0) -> 0 | AJ24: =IF($AG24=0,"000",$AG24) -> 000 | AK24: =IF($AI24=0,"000",$AI24) -> 000 | AM24: =CONCATENATE("км ",AF24,"+",AJ24," - км ",AH24,"+",AK24) -> км 0+000 - км 0+000 | AN24: =IF(ISBLANK($M24),N24&O24&P24&Q24&R24&S24&T24&U24,N24&O24&P24&Q24&R24&S24&T24&U24&";") | AO24: =UPPER(LEFT($AN24,1))&RIGHT(LOWER($AN24),LEN($AN24)-1) -> #VALUE! | AP24: =MIN(V24:AC24) -> 0 | AQ24: =AP24*C24 -> 0 | AS24: =AD24 -> 0 | AT24: =AE24 -> 0 | AU24: =E24 -> 0 | AV24: =D24 -> 0 | AW24: =IF(AP24=0,"-",AP24) -> - | AY24: =$AM24 -> км 0+000 - км 0+000 | AZ24: =$AW24 -> - | BA24: =$BE24 -> 0.5 | BD24: =$AM24 -> км 0+000 - км 0+000 | BE24: =ROUND(1-((5-$AP24)/10),2) -> 0.5 | BF24: =ROUND(BE24*$N$4,0) -> #N/A
... A131: =B130 -> 0 | C131: =B131-A131 -> 0 | N131: =IFERROR(VLOOKUP($F131,Лист1!$A$4:$F$72,2,FALSE),"") | O131: =IFERROR(VLOOKUP($G131,Лист1!$A$4:$F$72,2,FALSE),"") | P131: =IFERROR(VLOOKUP($H131,Лист1!$A$4:$F$72,2,FALSE),"") | Q131: =IFERROR(VLOOKUP($I131,Лист1!$A$4:$F$72,2,FALSE),"") | R131: =IFERROR(VLOOKUP($J131,Лист1!$A$4:$F$72,2,FALSE),"") | S131: =IFERROR(VLOOKUP($K131,Лист1!$A$4:$F$72,2,FALSE),"") | T131: =IFERROR(VLOOKUP($L131,Лист1!$A$4:$F$72,2,FALSE),"") | U131: =IF(ISBLANK($M131),"",$M131) | V131: =IFERROR(VLOOKUP($F131,Лист1!$A$4:$F$72,3,FALSE),"") | W131: =IFERROR(VLOOKUP($G131,Лист1!$A$4:$F$72,3,FALSE),"") | X131: =IFERROR(VLOOKUP($H131,Лист1!$A$4:$F$72,3,FALSE),"") | Y131: =IFERROR(VLOOKUP($I131,Лист1!$A$4:$F$72,3,FALSE),"") | Z131: =IFERROR(VLOOKUP($J131,Лист1!$A$4:$F$72,3,FALSE),"") | AA131: =IFERROR(VLOOKUP($K131,Лист1!$A$4:$F$72,3,FALSE),"") | AB131: =IFERROR(VLOOKUP($L131,Лист1!$A$4:$F$72,3,FALSE),"") | AC131: =IFERROR(VLOOKUP($M131,Лист1!$A$4:$F$72,3,FALSE),"") | AD131: =ROUND(AE130,3) -> 0 | AE131: =ROUND(AD131+C131,3) -> 0 | AF131: =ROUND(ROUNDDOWN(AD131,0),0) -> 0 | AG131: =ROUND((AD131-AF131)*1000,0) -> 0 | AH131: =ROUND(ROUNDDOWN(AE131,0),0) -> 0 | AI131: =ROUND((AE131-AH131)*1000,0) -> 0 | AJ131: =IF($AG131=0,"000",$AG131) -> 000 | AK131: =IF($AI131=0,"000",$AI131) -> 000 | AM131: =CONCATENATE("км ",AF131,"+",AJ131," - км ",AH131,"+",AK131) -> км 0+000 - км 0+000 | AN131: =IF(ISBLANK($M131),N131&O131&P131&Q131&R131&S131&T131&U131,N131&O131&P131&Q131&R131&S131&T131&U131&";") | AO131: =UPPER(LEFT($AN131,1))&RIGHT(LOWER($AN131),LEN($AN131)-1) -> #VALUE! | AP131: =MIN(V131:AC131) -> 0 | AQ131: =AP131*C131 -> 0 | AS131: =AD131 -> 0 | AT131: =AE131 -> 0 | AU131: =E131 -> 0 | AV131: =D131 -> 0 | AW131: =IF(AP131=0,"-",AP131) -> - | AY131: =$AM131 -> км 0+000 - км 0+000 | AZ131: =$AW131 -> - | BA131: =$BE131 -> 0.5 | BD131: =$AM131 -> км 0+000 - км 0+000 | BE131: =ROUND(1-((5-$AP131)/10),2) -> 0.5 | BF131: =ROUND(BE131*$N$4,0) -> #N/A
